{"uuid": "e6ad6545-fd6e-4b29-8dd6-70925fe54e49", "children": ["2c91f844-10f0-491e-bfd5-09c9314475c1"], "befores": [{"name": "get_global_cookie", "status": "broken", "statusDetails": {"message": "urllib3.exceptions.MaxRetryError: HTTPConnectionPool(host='localhost', port=49390): Max retries exceeded with url: /session/ecb37369-bf11-402c-aa68-761f5ed66113/cookie (Caused by NewConnectionError('<urllib3.connection.HTTPConnection object at 0x000002C9C3A2AF80>: Failed to establish a new connection: [WinError 10061] 由于目标计算机积极拒绝，无法连接。'))\n", "trace": "  File \"d:\\pycharm\\venv\\lib\\site-packages\\pluggy\\callers.py\", line 187, in _multicall\n    res = hook_impl.function(*args)\n  File \"d:\\pycharm\\venv\\lib\\site-packages\\_pytest\\fixtures.py\", line 1111, in pytest_fixture_setup\n    result = call_fixture_func(fixturefunc, request, kwargs)\n  File \"d:\\pycharm\\venv\\lib\\site-packages\\_pytest\\fixtures.py\", line 890, in call_fixture_func\n    fixture_result = fixturefunc(**kwargs)\n  File \"D:\\pycharm\\代码\\iptv\\test_case\\conftest.py\", line 32, in get_global_cookie\n    cookies = driver.get_cookies()\n  File \"d:\\pycharm\\venv\\lib\\site-packages\\selenium\\webdriver\\remote\\webdriver.py\", line 1074, in get_cookies\n    return self.execute(Command.GET_ALL_COOKIES)['value']\n  File \"d:\\pycharm\\venv\\lib\\site-packages\\selenium\\webdriver\\remote\\webdriver.py\", line 423, in execute\n    response = self.command_executor.execute(driver_command, params)\n  File \"d:\\pycharm\\venv\\lib\\site-packages\\selenium\\webdriver\\remote\\remote_connection.py\", line 333, in execute\n    return self._request(command_info[0], url, body=data)\n  File \"d:\\pycharm\\venv\\lib\\site-packages\\selenium\\webdriver\\remote\\remote_connection.py\", line 355, in _request\n    resp = self._conn.request(method, url, body=body, headers=headers)\n  File \"d:\\pycharm\\venv\\lib\\site-packages\\urllib3\\request.py\", line 74, in request\n    return self.request_encode_url(\n  File \"d:\\pycharm\\venv\\lib\\site-packages\\urllib3\\request.py\", line 96, in request_encode_url\n    return self.urlopen(method, url, **extra_kw)\n  File \"d:\\pycharm\\venv\\lib\\site-packages\\urllib3\\poolmanager.py\", line 375, in urlopen\n    response = conn.urlopen(method, u.request_uri, **kw)\n  File \"d:\\pycharm\\venv\\lib\\site-packages\\urllib3\\connectionpool.py\", line 813, in urlopen\n    return self.urlopen(\n  File \"d:\\pycharm\\venv\\lib\\site-packages\\urllib3\\connectionpool.py\", line 813, in urlopen\n    return self.urlopen(\n  File \"d:\\pycharm\\venv\\lib\\site-packages\\urllib3\\connectionpool.py\", line 813, in urlopen\n    return self.urlopen(\n  File \"d:\\pycharm\\venv\\lib\\site-packages\\urllib3\\connectionpool.py\", line 785, in urlopen\n    retries = retries.increment(\n  File \"d:\\pycharm\\venv\\lib\\site-packages\\urllib3\\util\\retry.py\", line 592, in increment\n    raise MaxRetryError(_pool, url, error or ResponseError(cause))\n"}, "start": 1650596652953, "stop": 1650596669199}], "start": 1650596652953, "stop": 1650596669715}