{"uuid": "f23801c9-ec2b-460c-9cc9-0d8b23c5c8be", "children": ["ee308ace-94a4-44fe-abf0-dfb7b79d65a0"], "befores": [{"name": "manager_brower", "status": "broken", "statusDetails": {"message": "urllib3.exceptions.MaxRetryError: HTTPConnectionPool(host='localhost', port=49390): Max retries exceeded with url: /session/ecb37369-bf11-402c-aa68-761f5ed66113/window/maximize (Caused by NewConnectionError('<urllib3.connection.HTTPConnection object at 0x000002C9C3D276A0>: Failed to establish a new connection: [WinError 10061] 由于目标计算机积极拒绝，无法连接。'))\n", "trace": "  File \"d:\\pycharm\\venv\\lib\\site-packages\\pluggy\\callers.py\", line 187, in _multicall\n    res = hook_impl.function(*args)\n  File \"d:\\pycharm\\venv\\lib\\site-packages\\_pytest\\fixtures.py\", line 1111, in pytest_fixture_setup\n    result = call_fixture_func(fixturefunc, request, kwargs)\n  File \"d:\\pycharm\\venv\\lib\\site-packages\\_pytest\\fixtures.py\", line 883, in call_fixture_func\n    fixture_result = next(generator)\n  File \"D:\\pycharm\\代码\\iptv\\test_case\\conftest.py\", line 19, in manager_brower\n    driver.maximize_window()\n  File \"d:\\pycharm\\venv\\lib\\site-packages\\selenium\\webdriver\\remote\\webdriver.py\", line 985, in maximize_window\n    self.execute(command, params)\n  File \"d:\\pycharm\\venv\\lib\\site-packages\\selenium\\webdriver\\remote\\webdriver.py\", line 423, in execute\n    response = self.command_executor.execute(driver_command, params)\n  File \"d:\\pycharm\\venv\\lib\\site-packages\\selenium\\webdriver\\remote\\remote_connection.py\", line 333, in execute\n    return self._request(command_info[0], url, body=data)\n  File \"d:\\pycharm\\venv\\lib\\site-packages\\selenium\\webdriver\\remote\\remote_connection.py\", line 355, in _request\n    resp = self._conn.request(method, url, body=body, headers=headers)\n  File \"d:\\pycharm\\venv\\lib\\site-packages\\urllib3\\request.py\", line 78, in request\n    return self.request_encode_body(\n  File \"d:\\pycharm\\venv\\lib\\site-packages\\urllib3\\request.py\", line 170, in request_encode_body\n    return self.urlopen(method, url, **extra_kw)\n  File \"d:\\pycharm\\venv\\lib\\site-packages\\urllib3\\poolmanager.py\", line 375, in urlopen\n    response = conn.urlopen(method, u.request_uri, **kw)\n  File \"d:\\pycharm\\venv\\lib\\site-packages\\urllib3\\connectionpool.py\", line 813, in urlopen\n    return self.urlopen(\n  File \"d:\\pycharm\\venv\\lib\\site-packages\\urllib3\\connectionpool.py\", line 813, in urlopen\n    return self.urlopen(\n  File \"d:\\pycharm\\venv\\lib\\site-packages\\urllib3\\connectionpool.py\", line 813, in urlopen\n    return self.urlopen(\n  File \"d:\\pycharm\\venv\\lib\\site-packages\\urllib3\\connectionpool.py\", line 785, in urlopen\n    retries = retries.increment(\n  File \"d:\\pycharm\\venv\\lib\\site-packages\\urllib3\\util\\retry.py\", line 592, in increment\n    raise MaxRetryError(_pool, url, error or ResponseError(cause))\n"}, "start": 1650596686188, "stop": 1650596702409}], "start": 1650596686188, "stop": 1650596702734}